<?xml version="1.0" encoding="UTF-8"?>
<!-- Generated by org.testng.reporters.JUnitReportReporter -->
<testsuite skipped="2" hostname="DESKTOP-FUGQNF4" name="org.screen.ScreenshotWithFailedTestCase" tests="9" failures="2" timestamp="03 Feb 2023 05:58:15 GMT" time="59.893" errors="0">
  <testcase name="testB" time="7.901" classname="org.screen.ScreenshotWithFailedTestCase">
    <failure type="java.lang.AssertionError" message="The following asserts failed:
	Verify Lastname expected [jaya] but found [vijaya]">
      <![CDATA[java.lang.AssertionError: The following asserts failed:
Verify Lastname expected [jaya] but found [vijaya]
at org.testng.asserts.SoftAssert.assertAll(SoftAssert.java:43)
at org.screen.ScreenshotWithFailedTestCase.testB(ScreenshotWithFailedTestCase.java:91)
at sun.reflect.NativeMethodAccessorImpl.invoke0(Native Method)
at sun.reflect.NativeMethodAccessorImpl.invoke(Unknown Source)
at sun.reflect.DelegatingMethodAccessorImpl.invoke(Unknown Source)
at java.lang.reflect.Method.invoke(Unknown Source)
at org.testng.internal.MethodInvocationHelper.invokeMethod(MethodInvocationHelper.java:124)
at org.testng.internal.Invoker.invokeMethod(Invoker.java:583)
at org.testng.internal.Invoker.invokeTestMethod(Invoker.java:719)
at org.testng.internal.Invoker.invokeTestMethods(Invoker.java:989)
at org.testng.internal.TestMethodWorker.invokeTestMethods(TestMethodWorker.java:125)
at org.testng.internal.TestMethodWorker.run(TestMethodWorker.java:109)
at org.testng.TestRunner.privateRun(TestRunner.java:648)
at org.testng.TestRunner.run(TestRunner.java:505)
at org.testng.SuiteRunner.runTest(SuiteRunner.java:455)
at org.testng.SuiteRunner.runSequentially(SuiteRunner.java:450)
at org.testng.SuiteRunner.privateRun(SuiteRunner.java:415)
at org.testng.SuiteRunner.run(SuiteRunner.java:364)
at org.testng.SuiteRunnerWorker.runSuite(SuiteRunnerWorker.java:52)
at org.testng.SuiteRunnerWorker.run(SuiteRunnerWorker.java:84)
at org.testng.TestNG.runSuitesSequentially(TestNG.java:1208)
at org.testng.TestNG.runSuitesLocally(TestNG.java:1137)
at org.testng.TestNG.runSuites(TestNG.java:1049)
at org.testng.TestNG.run(TestNG.java:1017)
at org.testng.remote.AbstractRemoteTestNG.run(AbstractRemoteTestNG.java:114)
at org.testng.remote.RemoteTestNG.initAndRun(RemoteTestNG.java:251)
at org.testng.remote.RemoteTestNG.main(RemoteTestNG.java:77)
]]>
    </failure>
  </testcase> <!-- testB -->
  <testcase name="testF" time="0.177" classname="org.screen.ScreenshotWithFailedTestCase"/>
  <testcase name="testF" time="0.002" classname="org.screen.ScreenshotWithFailedTestCase"/>
  <testcase name="testC" time="0.003" classname="org.screen.ScreenshotWithFailedTestCase"/>
  <testcase name="testA" time="51.803" classname="org.screen.ScreenshotWithFailedTestCase">
    <failure type="java.lang.AssertionError" message="The following asserts failed:
	Verify user  expected [jay] but found [vijay]">
      <![CDATA[java.lang.AssertionError: The following asserts failed:
Verify user  expected [jay] but found [vijay]
at org.testng.asserts.SoftAssert.assertAll(SoftAssert.java:43)
at org.screen.ScreenshotWithFailedTestCase.testA(ScreenshotWithFailedTestCase.java:56)
at sun.reflect.NativeMethodAccessorImpl.invoke0(Native Method)
at sun.reflect.NativeMethodAccessorImpl.invoke(Unknown Source)
at sun.reflect.DelegatingMethodAccessorImpl.invoke(Unknown Source)
at java.lang.reflect.Method.invoke(Unknown Source)
at org.testng.internal.MethodInvocationHelper.invokeMethod(MethodInvocationHelper.java:124)
at org.testng.internal.Invoker.invokeMethod(Invoker.java:583)
at org.testng.internal.Invoker.invokeTestMethod(Invoker.java:719)
at org.testng.internal.Invoker.invokeTestMethods(Invoker.java:989)
at org.testng.internal.TestMethodWorker.invokeTestMethods(TestMethodWorker.java:125)
at org.testng.internal.TestMethodWorker.run(TestMethodWorker.java:109)
at org.testng.TestRunner.privateRun(TestRunner.java:648)
at org.testng.TestRunner.run(TestRunner.java:505)
at org.testng.SuiteRunner.runTest(SuiteRunner.java:455)
at org.testng.SuiteRunner.runSequentially(SuiteRunner.java:450)
at org.testng.SuiteRunner.privateRun(SuiteRunner.java:415)
at org.testng.SuiteRunner.run(SuiteRunner.java:364)
at org.testng.SuiteRunnerWorker.runSuite(SuiteRunnerWorker.java:52)
at org.testng.SuiteRunnerWorker.run(SuiteRunnerWorker.java:84)
at org.testng.TestNG.runSuitesSequentially(TestNG.java:1208)
at org.testng.TestNG.runSuitesLocally(TestNG.java:1137)
at org.testng.TestNG.runSuites(TestNG.java:1049)
at org.testng.TestNG.run(TestNG.java:1017)
at org.testng.remote.AbstractRemoteTestNG.run(AbstractRemoteTestNG.java:114)
at org.testng.remote.RemoteTestNG.initAndRun(RemoteTestNG.java:251)
at org.testng.remote.RemoteTestNG.main(RemoteTestNG.java:77)
]]>
    </failure>
  </testcase> <!-- testA -->
  <testcase name="testF" time="0.004" classname="org.screen.ScreenshotWithFailedTestCase"/>
  <testcase name="testE" time="0.003" classname="org.screen.ScreenshotWithFailedTestCase"/>
  <testcase name="testD" classname="org.screen.ScreenshotWithFailedTestCase">
    <skipped/>
  </testcase> <!-- testD -->
  <testcase name="testG" classname="org.screen.ScreenshotWithFailedTestCase">
    <skipped/>
  </testcase> <!-- testG -->
</testsuite> <!-- org.screen.ScreenshotWithFailedTestCase -->
